Workbook

Sheet Backlog
A1: Titre | B1: En tant que | C1: Je veux... | D1: ...afin de... | E1: Pondération | F1: Données nécessaires | G1: MoSCoW Priorité | H1: Estimation_Charge(jours ouvrées) | I1: Pondération | K1: Product_manager | M1: Data architect | O1: Data_scientist | Q1: ML_engineer | S1: Back_end_Dev | U1: Front_end_Dev | W1: DPO | Y1: Testeur_qualité
A2: Connexion via une adresse mail | B2: Utilisateur de l'application | C2: pouvoir me connecter à mon compte sur l'application mobile en utilisant une adresse mail | D2: voir les informations me concernant (infos personnelles, photos prises, articles suggérés, ...) | E2: 50 | F2: - adresse mail utilisateur - mot de passe | G2: MOYEN | H2: 10 | I2: 76 | J2: Must Have | K2: 0.1 | L2: =K2*H2 -> 1 | M2: 0 | N2: =M2*H2 -> 0 | O2: 0 | P2: =O2*H2 -> 0 | Q2: 0 | R2: =Q2*H2 -> 0 | S2: 0.4 | T2: =S2*H2 -> 4 | U2: 0.4 | V2: =U2*H2 -> 4 | W2: 0 | X2: =W2*H2 -> 0 | Y2: 0.1 | Z2: =Y2*H2 -> 1
A3: Créer un compte | B3: Utilisateur de l'application | C3: pouvoir me créer un compte sur l'application mobile en utilisant une adresse mail et un mot de passe | D3: voir les informations me concernant (infos personnelles, photos prises, articles suggérés, ...) | E3: 50 | F3: - adresse mail utilisateur - mot de passe | G3: MOYEN | H3: 25 | I3: 76 | J3: Must Have | K3: 0.08 | L3: =K3*H3 -> 2 | M3: 0 | N3: =M3*H3 -> 0 | O3: 0 | P3: =O3*H3 -> 0 | Q3: 0 | R3: =Q3*H3 -> 0 | S3: 0.6 | T3: =S3*H3 -> 15 | U3: 0.28 | V3: =U3*H3 -> 7 | W3: 0 | X3: =W3*H3 -> 0 | Y3: 0.04 | Z3: =Y3*H3 -> 1
A4: Accéder à un outil de recommandation: Prendre et gérer mes photos | B4: Utilisateur de l'application | C4: prendre des photos | D4: constituer et gérer une collection personnelle de vêtements | E4: 51 | F4: -apparel photo | G4: HAUTE | H4: 20 | I4: 76 | J4: Must Have | K4: 0.1 | L4: =K4*H4 -> 2 | M4: 0 | N4: =M4*H4 -> 0 | O4: 0 | P4: =O4*H4 -> 0 | Q4: 0 | R4: =Q4*H4 -> 0 | S4: 0.4 | T4: =S4*H4 -> 8 | U4: 0.4 | V4: =U4*H4 -> 8 | W4: 0 | X4: =W4*H4 -> 0 | Y4: 0.1 | Z4: =Y4*H4 -> 2
A5: Accéder à un outil de recommandation: avoir des proposition de vêtements | B5: Utilisateur de l'application | C5: stocker mes photos correspondants à mes goûts | D5: bénéficier de propositions de vêtements par l'algorithme de l'application. | E5: 51 | F5: - photos - annotatons (menton j'ame, ms en favors, commentares) | G5: HAUTE | H5: 10 | I5: 76 | J5: Must Have | K5: 0.1 | L5: =K5*H5 -> 1 | M5: 0 | N5: =M5*H5 -> 0 | O5: 0 | P5: =O5*H5 -> 0 | Q5: 0 | R5: =Q5*H5 -> 0 | S5: 0.4 | T5: =S5*H5 -> 4 | U5: 0.4 | V5: =U5*H5 -> 4 | W5: 0 | X5: =W5*H5 -> 0 | Y5: 0.1 | Z5: =Y5*H5 -> 1
A6: Accéder à un outil de recommandation: Try-on | B6: Utilisateur de l'application | C6: que le vêtement soit afficher sur mes photos | D6: juger et décider si le vêtement proposé me convient | E6: 70 | F6: - photos de l'utlsateur - mage des vêtements | G6: HAUTE | H6: 251 | I6: 100 | J6: Must Have | K6: 0.05 | L6: =K6*H6 -> 12.55 | M6: 0.03 | N6: =M6*H6 -> 7.53 | O6: 0.5 | P6: =O6*H6 -> 125.5 | Q6: 0.3 | R6: =Q6*H6 -> 75.3 | S6: 0.05 | T6: =S6*H6 -> 12.55 | U6: 0.05 | V6: =U6*H6 -> 12.55 | W6: 0.01 | X6: =W6*H6 -> 2.51 | Y6: 0.01 | Z6: =Y6*H6 -> 2.51
A7: Accéder à un outil de recommandation: Personnalisation | B7: Utilisateur de l'application | C7: pouvoir changer la couleur et le style du vêtement recommandé | D7: choisir le style et la couleur qui me plaisent | E7: 60 | F7: - mage des vêtements | G7: HAUTE | H7: 251 | I7: 100 | J7: Must Have | K7: 0.05 | L7: =K7*H7 -> 12.55 | M7: 0.03 | N7: =M7*H7 -> 7.53 | O7: 0.5 | P7: =O7*H7 -> 125.5 | Q7: 0.3 | R7: =Q7*H7 -> 75.3 | S7: 0.05 | T7: =S7*H7 -> 12.55 | U7: 0.05 | V7: =U7*H7 -> 12.55 | W7: 0.01 | X7: =W7*H7 -> 2.51 | Y7: 0.01 | Z7: =Y7*H7 -> 2.51
A8: Accéder à un outil de recommandation: Favoris | B8: Utilisateur de l'application | C8: pouvoir définir ses styles préférés parmi ceux proposé par le site | D8: recevoir des recommandations plus pertinentes et adaptées à mes préférences et de constituer une collection d'articles personnalisés. | E8: 50 | G8: MOYEN | H8: 20 | I8: 25 | J8: Would Have | K8: 0.08 | L8: =K8*H8 -> 1.6 | M8: 0 | N8: =M8*H8 -> 0 | O8: 0 | P8: =O8*H8 -> 0 | Q8: 0 | R8: =Q8*H8 -> 0 | S8: 0.6 | T8: =S8*H8 -> 12 | U8: 0.28 | V8: =U8*H8 -> 5.6 | W8: 0 | X8: =W8*H8 -> 0 | Y8: 0.04 | Z8: =Y8*H8 -> 0.8
A9: Accéder à un outil de recommandation: Preferences des marques | B9: Utilisateur de l'application | C9: pouvoir référencer ses marques préférées parmi celles vendues par le groupe Fashion-Insta | D9: de recevoir des recommandations vestimentaires par marque. | E9: 51 | G9: HAUTE | H9: 25 | I9: 25 | J9: Would Have | K9: 0.08 | L9: =K9*H9 -> 2 | M9: 0 | N9: =M9*H9 -> 0 | O9: 0 | P9: =O9*H9 -> 0 | Q9: 0 | R9: =Q9*H9 -> 0 | S9: 0.6 | T9: =S9*H9 -> 15 | U9: 0.28 | V9: =U9*H9 -> 7 | W9: 0 | X9: =W9*H9 -> 0 | Y9: 0.04 | Z9: =Y9*H9 -> 1
A10: Accéder à un outil de recommandation: influenceurs | B10: Utilisateur de l'application | C10: pouvoir référencer les blogs, sites, de conseil, d’influenceur(seuses), de tendances | D10: de recevoir des recommandations de style vestimentaire par influenceurs. | E10: 51 | G10: HAUTE | H10: 25 | I10: 25 | J10: Would Have | K10: 0.08 | L10: =K10*H10 -> 2 | M10: 0 | N10: =M10*H10 -> 0 | O10: 0 | P10: =O10*H10 -> 0 | Q10: 0 | R10: =Q10*H10 -> 0 | S10: 0.6 | T10: =S10*H10 -> 15 | U10: 0.28 | V10: =U10*H10 -> 7 | W10: 0 | X10: =W10*H10 -> 0 | Y10: 0.04 | Z10: =Y10*H10 -> 1
A11: Accéder à un outil de recommandation: proposition personnalisées | B11: Utilisateur de l'application | C11: pouvoir à partir des préférences de l’utilisateur (styles, marques, blogs, …) proposer des vêtements. | D11: recevoir des recommandations plus pertinentes et adaptées à mes préférences. | E11: 70 | G11: HAUTE | H11: 25 | I11: 25 | J11: Would Have | K11: 0.08 | L11: =K11*H11 -> 2 | M11: 0 | N11: =M11*H11 -> 0 | O11: 0 | P11: =O11*H11 -> 0 | Q11: 0 | R11: =Q11*H11 -> 0 | S11: 0.6 | T11: =S11*H11 -> 15 | U11: 0.28 | V11: =U11*H11 -> 7 | W11: 0 | X11: =W11*H11 -> 0 | Y11: 0.04 | Z11: =Y11*H11 -> 1
A12: Laisser un avis | B12: Utilisateur de l'application | C12: pouvor laisser un avis sur la pertinence des propositions | D12: améliorer la pertinence des recommandatons, avoir des recommandatons plus cohérentes, partager mon expérience et mon avis | E12: 20 | F12: - adresse mail utilisateur - mot de passe | G12: BASSE | H12: 20 | I12: 100 | J12: Must Have | K12: 0.15 | L12: =K12*H12 -> 3 | M12: 0.15 | N12: =M12*H12 -> 3 | O12: 0.3 | P12: =O12*H12 -> 6 | Q12: 0.28 | R12: =Q12*H12 -> 5.6 | S12: 0.05 | T12: =S12*H12 -> 1 | U12: 0.05 | V12: =U12*H12 -> 1 | W12: 0.01 | X12: =W12*H12 -> 0.2 | Y12: 0.01 | Z12: =Y12*H12 -> 0.2
A13: Passer commande | B13: Utilisateur de l'application | C13: mettre les produis dans un panier | D13: recevoir mon article | E13: 100 | F13: - adresse mail utilisateur - mot de passe | G13: TRES HAUTE | H13: 60 | I13: 75 | J13: Should Have | K13: 0.1 | L13: =K13*H13 -> 6 | M13: 0 | N13: =M13*H13 -> 0 | O13: 0 | P13: =O13*H13 -> 0 | Q13: 0 | R13: =Q13*H13 -> 0 | S13: 0.68 | T13: =S13*H13 -> 40.8 | U13: 0.2 | V13: =U13*H13 -> 12 | W13: 0 | X13: =W13*H13 -> 0 | Y13: 0.02 | Z13: =Y13*H13 -> 1.2
A14: Valider une commande | B14: Utilisateur de l'application | C14: réaliser une commande | D14: recevoir mon article | E14: 100 | F14: - adresse mail utilisateur - mot de passe | G14: TRES HAUTE | H14: 60 | I14: 75 | J14: Should Have | K14: 0.1 | L14: =K14*H14 -> 6 | M14: 0 | N14: =M14*H14 -> 0 | O14: 0 | P14: =O14*H14 -> 0 | Q14: 0 | R14: =Q14*H14 -> 0 | S14: 0.68 | T14: =S14*H14 -> 40.8 | U14: 0.2 | V14: =U14*H14 -> 12 | W14: 0.01 | X14: =W14*H14 -> 0.6 | Y14: 0.01 | Z14: =Y14*H14 -> 0.6
A15: Choisir un type de livraison | B15: Utilisateur de l'application | C15: choisir le mode de livraison | D15: recevoir mon article | E15: 76 | F15: - adresse mail utilisateur - mot de passe - adresse postale - numéro de téléphone - condtons lvrasonsdes partenares | G15: TRES HAUTE | H15: 60 | I15: 75 | J15: Should Have | K15: 0.1 | L15: =K15*H15 -> 6 | M15: 0 | N15: =M15*H15 -> 0 | O15: 0 | P15: =O15*H15 -> 0 | Q15: 0 | R15: =Q15*H15 -> 0 | S15: 0.68 | T15: =S15*H15 -> 40.8 | U15: 0.2 | V15: =U15*H15 -> 12 | W15: 0.01 | X15: =W15*H15 -> 0.6 | Y15: 0.01 | Z15: =Y15*H15 -> 0.6
A16: Transaction bancaire | B16: Utilisateur de l'application | C16: pouvor réaliser une transaction | D16: recevoir mon article | E16: 100 | F16: - Nom et Prénom - adresse mail utilisateur - mot de passe - RB - condtons de paements s paement en pluseurs fos | G16: TRES HAUTE | H16: 60 | I16: 75 | J16: Should Have | K16: 0.1 | L16: =K16*H16 -> 6 | M16: 0 | N16: =M16*H16 -> 0 | O16: 0 | P16: =O16*H16 -> 0 | Q16: 0 | R16: =Q16*H16 -> 0 | S16: 0.68 | T16: =S16*H16 -> 40.8 | U16: 0.2 | V16: =U16*H16 -> 12 | W16: 0.01 | X16: =W16*H16 -> 0.6 | Y16: 0.01 | Z16: =Y16*H16 -> 0.6
A17: RGPD | B17: Utilisateur de l'application | C17: gérer la désinscription au service de recommandation | D17: exercer mes droits sur l’utilisation de mes données personnelles conformément au RGPD. | E17: 76 | F17: - adresse mail utilisateur - mot de passe | G17: TRES HAUTE | H17: 20 | I17: 11 | J17: Would Have | K17: 0.1 | L17: =K17*H17 -> 2 | M17: 0 | N17: =M17*H17 -> 0 | O17: 0 | P17: =O17*H17 -> 0 | Q17: 0 | R17: =Q17*H17 -> 0 | S17: 0.4 | T17: =S17*H17 -> 8 | U17: 0.2 | V17: =U17*H17 -> 4 | W17: 0.2 | X17: =W17*H17 -> 4 | Y17: 0.1 | Z17: =Y17*H17 -> 2
A18: RGPD | B18: Utilisateur de l'application | C18: accéder à la modifications et suppression des données personnelles | D18: contrôler l’usage de mes données personnelles et garantir le respect de mes droits conformément au RGPD | E18: 76 | F18: - adresse mail utilisateur - mot de passe | G18: TRES HAUTE | H18: 20 | I18: 11 | J18: Would Have | K18: 0.1 | L18: =K18*H18 -> 2 | M18: 0 | N18: =M18*H18 -> 0 | O18: 0 | P18: =O18*H18 -> 0 | Q18: 0 | R18: =Q18*H18 -> 0 | S18: 0.4 | T18: =S18*H18 -> 8 | U18: 0.2 | V18: =U18*H18 -> 4 | W18: 0.2 | X18: =W18*H18 -> 4 | Y18: 0.1 | Z18: =Y18*H18 -> 2
A19: RGPD | B19: Utilisateur de l'application | C19: gérer la durée de conservation de ses données personnelles | D19: maîtriser la façon dont mes données sont conservées et respecter mon droit à l’oubli conformément au RGPD | E19: 76 | F19: - adresse mail utilisateur - mot de passe | G19: TRES HAUTE | H19: 20 | I19: 11 | J19: Would Have | K19: 0.1 | L19: =K19*H19 -> 2 | M19: 0 | N19: =M19*H19 -> 0 | O19: 0 | P19: =O19*H19 -> 0 | Q19: 0 | R19: =Q19*H19 -> 0 | S19: 0.4 | T19: =S19*H19 -> 8 | U19: 0.2 | V19: =U19*H19 -> 4 | W19: 0.2 | X19: =W19*H19 -> 4 | Y19: 0.1 | Z19: =Y19*H19 -> 2
A20: RGPD | B20: Délégué à la proctecton des données (DPO) | C20: réaliser une purge automatique des données personnelles au bout d’un délai maximum fixé sans activité de l’utilisateur | D20: garantir la conformité de l’application avec les obligations légales de limitation de conservation des données selon le RGPD | E20: 76 | F20: - nom utilisateur | G20: TRES HAUTE | H20: 20 | I20: 11 | J20: Would Have | K20: 0.1 | L20: =K20*H20 -> 2 | M20: 0 | N20: =M20*H20 -> 0 | O20: 0 | P20: =O20*H20 -> 0 | Q20: 0 | R20: =Q20*H20 -> 0 | S20: 0.4 | T20: =S20*H20 -> 8 | U20: 0 | V20: =U20*H20 -> 0 | W20: 0.4 | X20: =W20*H20 -> 8 | Y20: 0.1 | Z20: =Y20*H20 -> 2
D21: TOTAL JOURS | H21: =SUM(H2:H20) -> 1002 | L21: =SUM(L2:L20) -> 73.7 | N21: =SUM(N2:N20) -> 18.06 | P21: =SUM(P2:P20) -> 257 | R21: =SUM(R2:R20) -> 156.2 | T21: =SUM(T2:T20) -> 309.3 | V21: =SUM(V2:V20) -> 135.7 | X21: =SUM(X2:X20) -> 27.02 | Z21: =SUM(Z2:Z20) -> 25.02
A23: MoSCoW Priorité | B23: Pondération | C23: Légende
A24: TRES HAUTE | B24: 76-100 | C24: Must Have
A25: HAUTE | B25: 51-75 | C25: Should Have
A26: MOYEN | B26: 26-50 | C26: Could Have
A27: BASSE | B27: 11-25 | C27: Would Have
A28: TRES BASSE | B28: 0-10 | C28: Won't Have
A30: Coûts main d'œuvre
A32: Profil Senior 5-10 ans*
A33: Profil | B33: Rôles | C33: Total (J) | D33: Salaire mensuel + charges | H33: Coût journalier | I33: Coût par Rôle
A34: Développeur Front-End | B34: Il conçoit et développe l’interface utilisateur de l’application Fashion-Insta, en traduisant les maquettes en pages web interactives et responsives. Il assure une navigation fluide pour les fonctionnalités clés : création de compte, gestion de garde-robe, et panier. | C34: =V21 -> 135.7 | D34: =120000/12 -> 10000 | H34: =250*2 -> 500 | I34: =H34*C34 -> 67850
A35: Développeur Back-End | B35: Il conçoit et met en place la logique serveur de l’application Fashion-Insta, en assurant la gestion des données, des comptes utilisateurs et des transactions. Il développe les API nécessaires aux échanges entre le front-end, les bases de données et les algorithmes de recommandation. Il garantit la sécurité, et la performance des traitements côté serveur. Il traite aussi les bugs. | C35: =T21 -> 309.3 | D35: =130000/12 -> 10833.333 | H35: =270.83*2 -> 541.66 | I35: =H35*C35 -> 167535.44
A36: Data architect | B36: Il conçoit l’architecture des données de l’application Fashion-Insta, en structurant les bases de données pour répondre aux besoins fonctionnels et de performance. Il définit les modèles de données pour les utilisateurs, les vêtements, les recommandations et les préférences. Il veille à la conformité des flux de données avec le RGPD et optimise leur accessibilité pour les développeurs et les algorithmes. | C36: =N21 -> 18.06 | D36: =190000/12 -> 15833.333 | H36: =395.83*2 -> 791.66 | I36: =H36*C36 -> 14297.38
A37: Data Scientist | B37: Il développe les algorithmes de recommandation de vêtements en exploitant les données issues des photos, des préférences utilisateurs et des tendances. Il entraîne et évalue des modèles d’IA pour les recommandations, personnaliser les suggestions de styles et visualiser les vêtements sur l’utilisateur. | C37: =P21 -> 257 | D37: =120000/12 -> 10000 | H37: =250*2 -> 500 | I37: =H37*C37 -> 128500
A38: ML engineer | B38: Il industrialise et déploie les modèles développés par le data scientist dans l’environnement de production de Fashion-Insta. Il s’assure que les algorithmes de recommandation fonctionnent de façon performante, scalable et sécurisée. Il met en place les pipelines de traitement, le monitoring des modèles et leur mise à jour continue. | C38: =R21 -> 156.2 | D38: =120000/12 -> 10000 | H38: =250*2 -> 500 | I38: =H38*C38 -> 78100
A39: DPO (Délégué à la Proctetion des Données) | B39: Il veille à la conformité de l’application Fashion-Insta avec le RGPD, en encadrant la collecte, le traitement et la conservation des données personnelles. Il définit les politiques de gestion des droits utilisateurs (accès, modification, suppression) et supervise la mise en œuvre de la purge automatique. Il travaille en étroite collaboration avec les équipes data pour garantir la protection des données dès la conception. | C39: =X21 -> 27.02 | D39: =110000/12 -> 9166.6667 | H39: =229.16*2 -> 458.32 | I39: =H39*C39 -> 12383.806
A40: Product Manager (Scrum master) | B40: Il pilote le projet Fashion-Insta en assurant la cohérence entre les besoins métiers et les livrables techniques. Il organise les sprints, anime les cérémonies Scrum et veille au respect des délais et priorités. Il facilite la communication entre les équipes (technique, design, data, métier) pour garantir la livraison d’un produit de qualité. | C40: =L21 -> 73.7 | D40: =110000/12 -> 9166.6667 | H40: =229.16*2 -> 458.32 | I40: =H40*C40 -> 33778.184
A41: Testeur | B41: Il vérifie que toutes les fonctionnalités de l’application Fashion-Insta répondent aux exigences définies dans le cahier des charges. Il conçoit et exécute des tests fonctionnels, techniques et RGPD pour détecter les anomalies avant la mise en production. Il rédige les rapports de tests et collabore avec les développeurs pour assurer la qualité et la stabilité de l’application. | C41: =Z21 -> 25.02 | D41: =70000/12 -> 5833.3333 | H41: =145.83*2 -> 291.66 | I41: =H41*C41 -> 7297.3332
A42: TOTAL | C42: =SUM(C34:C41) -> 1002 | D42: =SUM(D34:D41) -> 80833.333 | H42: =SUM(H34:H41) -> 4041.62 | I42: =SUM(I34:I41) -> 509742.14
A43: *TJM (en € sur régon parsenne pour un profl ayant entre 5 et 10 ans d'expérience selon Page personnel)
...

Sheet Rentabilité
A1: PROJECTION DU CHIFFRE D'AFFAIRES
A3: Variables | B3: Valeur
A4: Nombre de visiteurs T0(lancement) | B4: 120000
A5: Taux de conversion | B5: 0.1
A6: Nombre de clients actifs | B6: =B4*(10/100) -> 12000
A7: Panier moyen | B7: 60
A8: Commission | B8: =B7*(5/100) -> 3
A9: Publicité | B9: 0.1 | C9: pour 1000 vues
A11: Année | B11: Nbr de visiteurs | C11: Nbr de clients actifs | D11: Gains par transactions | E11: Gains publicité | F11: Gains projetés
A12: 47849 | B12: 120000 | C12: =ROUNDUP(B12*$B$5,0) -> 12000 | D12: =(C12*$B$8) -> 36000 | E12: =(((B12/1000)*$B$9)*10)*12 -> 1440 | F12: =D12+E12 -> 37440
A13: 47880 | B13: =B12*1.1 -> 132000 | C13: =ROUNDUP(B13*$B$5,0) -> 13200 | D13: =(C13*$B$8) -> 39600 | E13: =(((B13/1000)*$B$9)*10)*12 -> 1584 | F13: =D13+E13 -> 41184
A14: 47908 | B14: =B13*1.1 -> 145200 | C14: =ROUNDUP(B14*$B$5,0) -> 14520 | D14: =(C14*$B$8) -> 43560 | E14: =(((B14/1000)*$B$9)*10)*12 -> 1742.4 | F14: =D14+E14 -> 45302.4
A15: 47939 | B15: =B14*1.1 -> 159720 | C15: =ROUNDUP(B15*$B$5,0) -> 15972 | D15: =(C15*$B$8) -> 47916 | E15: =(((B15/1000)*$B$9)*10)*12 -> 1916.64 | F15: =D15+E15 -> 49832.64
A16: 47969 | B16: =B15*1.1 -> 175692 | C16: =ROUNDUP(B16*$B$5,0) -> 17570 | D16: =(C16*$B$8) -> 52710 | E16: =(((B16/1000)*$B$9)*10)*12 -> 2108.304 | F16: =D16+E16 -> 54818.304
A17: 48000 | B17: =B16*1.1 -> 193261.2 | C17: =ROUNDUP(B17*$B$5,0) -> 19327 | D17: =(C17*$B$8) -> 57981 | E17: =(((B17/1000)*$B$9)*10)*12 -> 2319.1344 | F17: =D17+E17 -> 60300.134
A18: 48030 | B18: =B17*1.1 -> 212587.32 | C18: =ROUNDUP(B18*$B$5,0) -> 21259 | D18: =(C18*$B$8) -> 63777 | E18: =(((B18/1000)*$B$9)*10)*12 -> 2551.0478 | F18: =D18+E18 -> 66328.048
A19: 48061 | B19: =B18*1.1 -> 233846.05 | C19: =ROUNDUP(B19*$B$5,0) -> 23385 | D19: =(C19*$B$8) -> 70155 | E19: =(((B19/1000)*$B$9)*10)*12 -> 2806.1526 | F19: =D19+E19 -> 72961.153
A20: 48092 | B20: =B19*1.1 -> 257230.66 | C20: =ROUNDUP(B20*$B$5,0) -> 25724 | D20: =(C20*$B$8) -> 77172 | E20: =(((B20/1000)*$B$9)*10)*12 -> 3086.7679 | F20: =D20+E20 -> 80258.768
A21: 48122 | B21: =B20*1.1 -> 282953.72 | C21: =ROUNDUP(B21*$B$5,0) -> 28296 | D21: =(C21*$B$8) -> 84888 | E21: =(((B21/1000)*$B$9)*10)*12 -> 3395.4447 | F21: =D21+E21 -> 88283.445
A22: 48153 | B22: =B21*1.1 -> 311249.1 | C22: =ROUNDUP(B22*$B$5,0) -> 31125 | D22: =(C22*$B$8) -> 93375 | E22: =(((B22/1000)*$B$9)*10)*12 -> 3734.9891 | F22: =D22+E22 -> 97109.989
A23: 48183 | B23: =B22*1.1 -> 342374 | C23: =ROUNDUP(B23*$B$5,0) -> 34238 | D23: =(C23*$B$8) -> 102714 | E23: =(((B23/1000)*$B$9)*10)*12 -> 4108.4881 | F23: =D23+E23 -> 106822.49
A24: 48214 | B24: =B23*1.1 -> 376611.41 | C24: =ROUNDUP(B24*$B$5,0) -> 37662 | D24: =(C24*$B$8) -> 112986 | E24: =(((B24/1000)*$B$9)*10)*12 -> 4519.3369 | F24: =D24+E24 -> 117505.34
... A71: 49644 | B71: =B70*1.1 -> 33216179 | C71: =ROUNDUP(B71*$B$5,0) -> 3321618 | D71: =(C71*$B$8) -> 9964854 | E71: =(((B71/1000)*$B$9)*10)*12 -> 398594.15 | F71: =D71+E71 -> 10363448
A73: CALCUL DE RENTABILITE (ROI)
A76: Mois/années | B76: Gains annuel projetés | C76: Coûts main d'oeuvre | D76: Coûts infrastructure (conception et entraînement des modèles) | E76: Coûts infrastructure (phase production) | F76: Coûts de maintenances (30% de l'infrastructure de prod) | G76: Cumul des coûts | H76: Cumul du CA | I76: ROI | J76: Bénéfices
A77: 46023 | B77: 0 | C77: =Backlog!$D$42*-1 -> -80833.333 | D77: =Backlog!$K$80*-1 -> -30209.384 | G77: =C77+D77 -> -111042.72 | H77: =B77 -> 0 | I77: =(IF(H77=0,1,H77)/G77)*-1 -> 9.0055433e-06 | J77: =G77+H77 -> -111042.72
A78: 46054 | B78: 0 | C78: =Backlog!$D$42*-1 -> -80833.333 | D78: =Backlog!$K$80*-1 -> -30209.384 | G78: =C78+D78+G77 -> -222085.43 | H78: =B78+H77 -> 0 | I78: =(IF(H78=0,1,H78)/G78)*-1 -> 4.5027716e-06 | J78: =G78+H78 -> -222085.43
A79: 46082 | B79: 0 | C79: =Backlog!$D$42*-1 -> -80833.333 | D79: =Backlog!$K$80*-1 -> -30209.384 | G79: =C79+D79+G78 -> -333128.15 | H79: =B79+H78 -> 0 | I79: =(IF(H79=0,1,H79)/G79)*-1 -> 3.0018478e-06 | J79: =G79+H79 -> -333128.15
A80: 46113 | B80: 0 | C80: =Backlog!$D$42*-1 -> -80833.333 | D80: =Backlog!$K$80*-1 -> -30209.384 | G80: =C80+D80+G79 -> -444170.87 | H80: =B80+H79 -> 0 | I80: =(IF(H80=0,1,H80)/G80)*-1 -> 2.2513858e-06 | J80: =G80+H80 -> -444170.87
A81: 46143 | B81: 0 | C81: =Backlog!$D$42*-1 -> -80833.333 | D81: =Backlog!$K$80*-1 -> -30209.384 | G81: =C81+D81+G80 -> -555213.59 | H81: =B81+H80 -> 0 | I81: =(IF(H81=0,1,H81)/G81)*-1 -> 1.8011087e-06 | J81: =G81+H81 -> -555213.59
A82: 46174 | B82: 0 | C82: =Backlog!$D$42*-1 -> -80833.333 | D82: =Backlog!$K$80*-1 -> -30209.384 | G82: =C82+D82+G81 -> -666256.3 | H82: =B82+H81 -> 0 | I82: =(IF(H82=0,1,H82)/G82)*-1 -> 1.5009239e-06 | J82: =G82+H82 -> -666256.3
A83: 46204 | B83: 0 | C83: =Backlog!$D$42*-1 -> -80833.333 | D83: =Backlog!$K$80*-1 -> -30209.384 | G83: =C83+D83+G82 -> -777299.02 | H83: =B83+H82 -> 0 | I83: =(IF(H83=0,1,H83)/G83)*-1 -> 1.2865062e-06 | J83: =G83+H83 -> -777299.02
A84: 46235 | B84: 0 | C84: =Backlog!$D$42*-1 -> -80833.333 | D84: =Backlog!$K$80*-1 -> -30209.384 | G84: =C84+D84+G83 -> -888341.74 | H84: =B84+H83 -> 0 | I84: =(IF(H84=0,1,H84)/G84)*-1 -> 1.1256929e-06 | J84: =G84+H84 -> -888341.74
A85: 46266 | B85: 0 | C85: =Backlog!$D$42*-1 -> -80833.333 | D85: =Backlog!$K$80*-1 -> -30209.384 | G85: =C85+D85+G84 -> -999384.46 | H85: =B85+H84 -> 0 | I85: =(IF(H85=0,1,H85)/G85)*-1 -> 1.0006159e-06 | J85: =G85+H85 -> -999384.46
A86: 46296 | B86: 0 | C86: =Backlog!$D$42*-1 -> -80833.333 | D86: =Backlog!$K$80*-1 -> -30209.384 | G86: =C86+D86+G85 -> -1110427.2 | H86: =B86+H85 -> 0 | I86: =(IF(H86=0,1,H86)/G86)*-1 -> 9.0055433e-07 | J86: =G86+H86 -> -1110427.2
A87: 46327 | B87: 0 | C87: =Backlog!$D$42*-1 -> -80833.333 | D87: =Backlog!$K$80*-1 -> -30209.384 | G87: =C87+D87+G86 -> -1221469.9 | H87: =B87+H86 -> 0 | I87: =(IF(H87=0,1,H87)/G87)*-1 -> 8.1868575e-07 | J87: =G87+H87 -> -1221469.9
A88: 46357 | B88: 0 | C88: =Backlog!$D$42*-1 -> -80833.333 | D88: =Backlog!$K$80*-1 -> -30209.384 | G88: =C88+D88+G87 -> -1332512.6 | H88: =B88+H87 -> 0 | I88: =(IF(H88=0,1,H88)/G88)*-1 -> 7.5046194e-07 | J88: =G88+H88 -> -1332512.6
A89: 46388 | B89: 0 | C89: =Backlog!$D$42*-1 -> -80833.333 | D89: =Backlog!$K$80*-1 -> -30209.384 | G89: =C89+D89+G88 -> -1443555.3 | H89: =B89+H88 -> 0 | I89: =(IF(H89=0,1,H89)/G89)*-1 -> 6.927341e-07 | J89: =G89+H89 -> -1443555.3
... A136: 47818 | B136: 0 | C136: =Backlog!$D$42*-1 -> -80833.333 | D136: =Backlog!$K$80*-1 -> -30209.384 | G136: =C136+D136+G135 -> -6662563 | H136: =B136+H135 -> 0 | I136: =(IF(H136=0,1,H136)/G136)*-1 -> 1.5009239e-07 | J136: =G136+H136 -> -6662563
A137: 47849 | B137: =F12 -> 37440 | C137: =Backlog!$D$42*-1 -> -80833.333 | E137: =Backlog!$K$115*-1 -> -49506.805 | F137: =(C137+E137)*0.15 -> -19551.021 | G137: =C137+E137+G136+F137 -> -6812454.2 | H137: =B137+H136 -> 37440 | I137: =(IF(H137=0,1,H137)/G137)*-1 -> 0.0054958168 | J137: =G137+H137 -> -6775014.2
...

Sheet Organisation SCRUM
A1: I. Rôles et Responsabilités
A2: Chef de Projet:
A3: Définit la vision du produit et établit les priorités des fonctionnalités.
A4: Représente les besoins des utilisateurs et des parties prenantes.
A5: Collabore avec l'équipe de développement pour assurer la livraison du produit attendu.
A6: Développeur Front-End:
A7: Conçoit et développe l'interface utilisateur de l'application mobile.
A8: Garantit la convivialité et l'ergonomie de l'application.
A9: Développeur Back-End:
A10: Développe l'architecture logicielle et les API back-end.
A11: Intègre les modèles d'apprentissage automatique.
A12: Gère les données et la base de données.
... A19: Le Sprint Planning est une réunion de début de sprint où sont définis les objectifs et les user stories. La charge de travail est estimée et les tâches sont réparties au sein de l'équipe.
B21: Durée : 1 à 2h
B22: Fréquence : Début de chaque sprint
B23: Participants : Chef de projet, Dev Front, Dev Back, Data Scientist
A25: Le Daily Scrum est une brève réunion quotidienne visant à synchroniser l'équipe, identifier les obstacles et ajuster le plan de travail si nécessaire.
B27: Durée : 15 mins
B28: Fréquence : Tous les jours ouvrables
B29: Participants : Chef de projet, Dev Front, Dev Back, Data Scientist
A31: La Sprint Review consiste à présenter les fonctionnalités achevées aux parties prenantes pour recueillir leurs retours et définir les priorités du sprint suivant.
B33: Durée : 1 à 2 heures
B34: Fréquence : Fin de chaque sprint
B35: Participants : Chef de projet, Dev front, Dev Back, Data Scientist et parties prenantes (Alicia la VP Product, équipe produit)
A37: La Sprint Retrospective est une réunion de fin de sprint pour analyser les réussites et les échecs, identifier les axes d'amélioration et renforcer la cohésion d'équipe.
B39: Durée : 1 à 2 heures
B40: Fréquence : Fin de chaque sprint
B41: Participants : Chef de projet, Dev front, Dev Back, Data Scientist
A45: III. Points de Suivi et de Pilotage
A46: Le Backlog Produit est une liste priorisée des User Stories (US) décrivant les fonctionnalités à développer.
B47: Chaque US doit être claire, concise, testable et inclure des critères de validation.
B48: Priorisation : La méthode MoSCoW (Must Have, Should Have, Could Have, Would Have, Nice to Have) est utilisée pour prioriser les US.
B49: Attention aux dépendances entre les tâches !
B50: Outils : Notion, Jira, Github
A52: Le Burndown Chart est un graphique qui visualise l'avancement du sprint en fonction du temps restant, basé sur les Story Points. Il permet d'identifier rapidement les problèmes et d'y remédier.
A55: Le Tableau de Sprint est un planning détaillé des tâches à accomplir pour chaque sprint.
B56: Contenu : Le tableau doit inclure : 1. les US à réaliser, 2. les tâches à réaliser, 3. Les participants,
B57: 4. Une estimation du temps nécessaire par tâche et 5. le statut de chaque tâche.
B58: Outils : Notion, Jira, Github

Sheet SPRINTS
A1: SPRINTS
A2: Description du jalon | B2: PRIORITE | C2: Attribué à | D2: Début | E2: Jours | F2: Fin | G2: Story point | H2: Product Manager (Scrum master) | I2: Data architect | J2: Développeur Front-End | K2: Développeur Back-End | L2: Data Scientist | M2: ML engineer | N2: DPO | O2: Testeur
A3: 1. LANCEMENT DE PROJET (SPRINT 1) | D3: 46024 | E3: 24 | F3: 46048 | G3: 206
A4: 1.a. Réunion de lancement projet | B4: TRES HAUTE | C4: Product Manager | D4: 46024 | E4: 1 | F4: 46024 | G4: 3 | H4: RA | I4: C | J4: C | K4: C | L4: C | M4: C | N4: C | O4: C
A5: 1.b. Etude des besoins | B5: TRES HAUTE | C5: Product Manager | D5: 46027 | E5: =F5-D5 -> 4 | F5: 46031 | G5: 75 | H5: RA | I5: C | J5: I | K5: I | L5: C | M5: I | N5: C
A6: 1.c. Rédaction du cahier des charges (backlog) | B6: TRES HAUTE | C6: Product Manager | D6: 46034 | E6: =F6-D6 -> 4 | F6: 46038 | G6: 50 | H6: RA | I6: C | J6: C | K6: C | L6: C | M6: I | N6: C
A7: 1.d. Clarification des besoins avec les métiers | B7: TRES HAUTE | C7: Product Manager | D7: 46041 | E7: =F7-D7 -> 4 | F7: 46045 | G7: 75 | H7: RA | I7: C | J7: C | K7: C | L7: C | M7: I | N7: C
A8: 1.e. Présentation note de cadrage, cahier des charges(backlog) | B8: Jalon | C8: Product Manager | D8: =D4+24 -> 46048 | E8: 1 | F8: 46048 | G8: 3 | H8: RA | I8: I | J8: I | K8: I | L8: I | M8: I | N8: I | O8: I
A9: 2. CONCEPTION (SPRINT 2) | D9: 46048 | E9: 4 | F9: 46052 | G9: 328
A10: 2.a. Définition de l'architecture de l'application | B10: TRES HAUTE | C10: Data architect | D10: 46048 | E10: =F10-D10 -> 4 | F10: 46052 | G10: 100 | H10: C | I10: RA | J10: C | K10: R | L10: R | M10: C | N10: C
A11: 2.b. Choix des technologies | B11: TRES HAUTE | C11: Data architect | D11: 46048 | E11: =F11-D11 -> 4 | F11: 46052 | G11: 50 | H11: C | I11: RA | J11: R | K11: RA | L11: R | M11: C | N11: C
A12: 2.c. Réalisation du schéma et des maquettes | B12: TRES HAUTE | C12: Data architect | D12: 46048 | E12: =F12-D12 -> 4 | F12: 46052 | G12: 100 | H12: C | I12: RA | J12: R | K12: RA | L12: R | M12: C | N12: C
A13: 2.d. Revue avec les métiers | B13: TRES HAUTE | C13: Product Manager | D13: 46052 | E13: 1 | F13: 46052 | G13: 75 | H13: RA | I13: C | J13: C | K13: C | L13: C | M13: I | N13: C
A14: 2.e. Présentation des wireframes, diagrame UML, prototypes figma | B14: Jalon | C14: Product Manager | D14: 46052 | E14: 1 | F14: 46052 | G14: 3 | H14: RA | I14: C | J14: C | K14: C | L14: C | M14: I | N14: C
A15: 3. DEVELOPPEMENT (SPRINT 3) | D15: 46055 | E15: 25 | F15: 46080 | G15: 73
A16: 3.a. Initialisation de l'environnement: CI/CD, Git, JIRA, Notion… | B16: TRES HAUTE | C16: Developpeur Back-end | D16: 46055 | E16: =F16-D16 -> 4 | F16: 46059 | G16: 30 | H16: C | I16: R | J16: R | K16: RA | L16: C | M16: I | N16: I
A17: 3.b. Création de l'authentification par adresse mail (inscription et connexion) | B17: TRES HAUTE | C17: Developpeur Back-end | D17: 46059 | E17: =F17-D17 -> 21 | F17: 46080 | G17: 30 | H17: A | I17: I | J17: R | K17: R | L17: I | M17: I | N17: I
A18: 3.b.1. Test du module authentification | B18: TRES HAUTE | C18: Testeur | D18: 46080 | E18: 1 | F18: 46080 | G18: 10 | J18: C | K18: C | O18: RA
A19: 3.b.2. Revue du rapport de test (replanification) | B19: Jalon | C19: Product Manager | D19: 46080 | E19: 1 | F19: 46080 | G19: 3 | H19: RA | I19: C | J19: C | K19: C | L19: I | M19: I | N19: C | O19: C
A20: 3. DEVELOPPEMENT (SPRINT 4) | D20: 46083 | E20: =F20-D20 -> 23 | F20: 46106 | G20: 43
A21: 3.c. Module prise de photo et gestion de collections personnelles de vêtements | B21: TRES HAUTE | C21: Developpeur Back-end | D21: 46083 | E21: =F21-D21 -> 18 | F21: 46101 | G21: 30 | H21: C | J21: R | K21: RA | N21: C
A22: 3.c.1. Test du module collection personnelle de vêtements | B22: TRES HAUTE | C22: Testeur | D22: 46104 | E22: =F22-D22 -> 2 | F22: 46106 | G22: 10 | J22: C | K22: C | O22: RA
A23: 3.c.2 Revue du rapport de test (replanification) | B23: Jalon | C23: Product Manager | D23: 46106 | E23: 1 | F23: 46106 | G23: 3 | H23: RA | I23: C | J23: C | K23: C | L23: I | M23: I | N23: C | O23: C
A24: 3. DEVELOPPEMENT (SPRINT 5) | D24: 46111 | E24: =F24-D24 -> 28 | F24: 46139 | G24: 100
A25: 3.d. Module d'essayage virtuel (Try-on) | B25: TRES HAUTE | C25: Data scientist | D25: 46111 | E25: =F25-D25 -> 28 | F25: 46139 | G25: 100 | H25: C | J25: R | K25: R | L25: RA | M25: R
A26: 3. DEVELOPPEMENT (SPRINT 6) | D26: 46140 | E26: =F26-D26 -> 28 | F26: 46168 | G26: 100
A27: 3.d. Module d'essayage virtuel (Try-on) | B27: TRES HAUTE | C27: Data scientist | D27: 46140 | E27: =F27-D27 -> 28 | F27: 46168 | G27: 100 | H27: C | J27: R | K27: R | L27: RA | M27: R
A28: 3. DEVELOPPEMENT (SPRINT 7) | D28: 46169 | E28: =F28-D28 -> 28 | F28: 46197 | G28: 100
A29: 3.d. Module d'essayage virtuel (Try-on) | B29: TRES HAUTE | C29: Data scientist | D29: 46169 | E29: =F29-D29 -> 28 | F29: 46197 | G29: 100 | H29: C | J29: R | K29: R | L29: RA | M29: R
A30: 3. DEVELOPPEMENT (SPRINT 8) | D30: 46198 | E30: =F30-D30 -> 29 | F30: 46227 | G30: 100
A31: 3.d. Module d'essayage virtuel (Try-on) | B31: TRES HAUTE | C31: Data scientist | D31: 46198 | E31: =F31-D31 -> 29 | F31: 46227 | G31: 100 | H31: C | J31: R | K31: R | L31: RA | M31: R
A32: 3. DEVELOPPEMENT (SPRINT 9) | D32: 46230 | E32: =F32-D32 -> 39 | F32: 46269 | G32: 100
A33: 3.d. Module d'essayage virtuel (Try-on) | B33: TRES HAUTE | C33: Data scientist | D33: 46230 | E33: =F33-D33 -> 39 | F33: 46269 | G33: 100 | H33: C | J33: R | K33: R | L33: RA | M33: R
A34: 3. DEVELOPPEMENT (SPRINT 10) | D34: 46272 | E34: =F34-D34 -> 25 | F34: 46297 | G34: 100
A35: 3.d. Module d'essayage virtuel (Try-on) | B35: TRES HAUTE | C35: Data scientist | D35: 46272 | E35: =F35-D35 -> 25 | F35: 46297 | G35: 100 | H35: C | J35: R | K35: R | L35: RA | M35: R
A36: 3. DEVELOPPEMENT (SPRINT 11) | D36: 46300 | E36: =F36-D36 -> 25 | F36: 46325 | G36: 100
A37: 3.d. Module d'essayage virtuel (Try-on) | B37: TRES HAUTE | C37: Data scientist | D37: 46300 | E37: =F37-D37 -> 25 | F37: 46325 | G37: 100 | H37: C | J37: R | K37: R | L37: RA | M37: R
A38: 3. DEVELOPPEMENT (SPRINT 12) | D38: 46328 | E38: =F38-D38 -> 28 | F38: 46356 | G38: 100
A39: 3.d. Module d'essayage virtuel (Try-on) | B39: TRES HAUTE | C39: Data scientist | D39: 46328 | E39: =F39-D39 -> 28 | F39: 46356 | G39: 100 | H39: C | J39: R | K39: R | L39: RA | M39: R
A40: 3. DEVELOPPEMENT (SPRINT 13) | D40: 46357 | E40: =F40-D40 -> 30 | F40: 46387 | G40: 100
...

Sheet Registre Traitements
A1: Coordonnées du responsable de l’organisme | B1: Nom : | C1: COMEX | D1: Prénom : | E1: JEAN | F1: Adresse : | G1: 139 rue de Charles de Gaulle | H1: Adresse mél : | I1: comex-jean@fashion-insta.com
A2: (responsable de traitement ou son représentant si le responsable est situé en dehors de l’UE) | B2: Code postal : | C2: 37000 | D2: Ville : | E2: TOURS | F2: Téléphone : | G2: 07XXXXXX
A3: Coordonnées du représentant | B3: Nom : | C3: MASTERS | D3: Prénom : | E3: ALICIA | F3: Adresse : | G3: 139 rue de Charles de Gaulle | H3: Adresse mél : | I3: masters-alicia@fashion-insta.com
A4: (responsable de traitement ou son représentant si le responsable est situé en dehors de l’UE) | B4: Code postal : | C4: 37000 | D4: Ville : | E4: TOURS | F4: Téléphone : | G4: 07XXXXXX
A5: Coordonnées du délégué à la protection des données (DPO) | B5: Nom : | C5: DEPEAU | D5: Prénom : | E5: ROMAIN | F5: Société (si DPO externe) : | H5: Adresse : | I5: 139 rue de Charles de Gaulle
B6: Code postal : | C6: 37000 | D6: Ville : | E6: TOURS | F6: Téléphone : | G6: 07XXXXXX | H6: Adresse mél : | I6: depeau-romain@fashion-insta.com
A7: Identification du traitement | E7: Finalité du traitement | H7: Données sensibles ?
A8: Nom du traitement | B8: N° / RÉF | C8: Date de création de la fiche | D8: Dernière mise à jour de la fiche | H8: Oui/non
A9: Compte utilisateur | B9: 1 - A | C9: 43246 | D9: 43598 | E9: Permettre aux utilisateurs de créer et de se connecter à un compte utilisateur pour gérer leurs données personnelles, réaliser des commandes, recevoir leurs livraisons. | H9: OUI
A10: Outil de recommandation | B10: 2- A | E10: Bénéficier de proposition de vêtement par l'agorithme de l'application | H10: OUI
A11: Try-on | B11: 3 - A | E11: Donne à l'utilisateur la possibilité de juger et décider si le vêtement proposé lui convient | H11: OUI
A12: Try-on | B12: 3 - A | E12: Permet à l'utilisateur de choisir le style et la couleur qui lui plaisent | H12: OUI
A13: Compte utilisateur | B13: 1- A | E13: Permet à l'utiliateur d'accéder à ses préférences (marques, vêtements, influenceurs) | H13: NON
A14: Outil de recommandation | B14: 2-A | E14: Bénéficier de préférences personnalisées par l'algorithme de l'application. | H14: NON
A15: Outil de recommandation | B15: 2-A | E15: Améliorer le contenu et l'expérience utilisateur de la plateforme. | H15: NON

Sheet Fiche Registre
A1: Description du traitement | J1: Description du traitement
A2: Nom du traitement | B2: Compte utilisateur | J2: Nom du traitement | K2: Outil de recommandation
A3: N° / RÉF | B3: 1 - A | J3: N° / RÉF | K3: 2 - A
A4: Date de création du traitement | J4: Date de création du traitement
A5: Mise à jour du traitement | J5: Mise à jour du traitement
A7: Acteurs | B7: Nom | C7: Adresse | D7: Code Postal | E7: Ville | F7: Pays | G7: Téléphone | H7: Adresse mél | J7: Acteurs | K7: Nom | L7: Adresse | M7: Code Postal | N7: Ville | O7: Pays | P7: Téléphone | Q7: Adresse mél
A8: Responsable du traitement | B8: COMEX JEAN | C8: 139 rue Charles de Gaulle | D8: 37000 | E8: TOURS | F8: FRANCE | G8: 07XXXXXXXX | H8: comex-jean@fashion-intsa.com | J8: Responsable du traitement | K8: COMEX JEAN | L8: 139 rue Charles de Gaulle | M8: 37000 | N8: TOURS | O8: FRANCE | P8: 07XXXXXXXX | Q8: comex-jean@fashion-intsa.com
A9: Délégué à la protection des données | B9: DEPEAU ROMAIN | C9: 139 rue Charles de Gaulle | D9: 37000 | E9: TOURS | F9: FRANCE | G9: 07XXXXXXXX | H9: depeau-romain@fashion-insta.com | J9: Délégué à la protection des données | K9: DEPEAU ROMAIN | L9: 139 rue Charles de Gaulle | M9: 37000 | N9: TOURS | O9: FRANCE | P9: 07XXXXXXXX | Q9: depeau-romain@fashion-insta.com
A10: Société du DPO (si celui-ci est externe) | B10: N/A | J10: Société du DPO (si celui-ci est externe) | K10: N/A
A11: Représentant | B11: MASTERS ALICIA | C11: 139 rue Charles de Gaulle | D11: 37000 | E11: TOURS | F11: FRANCE | G11: 07XXXXXXXX | H11: masters-alicia@fashion-insta.com | J11: Représentant | K11: MASTERS ALICIA | L11: 139 rue Charles de Gaulle | M11: 37000 | N11: TOURS | O11: FRANCE | P11: 07XXXXXXXX | Q11: masters-alicia@fashion-insta.com
A12: Responsable(s) conjoint(s) | J12: Responsable(s) conjoint(s)
A14: Finalité(s) du traitement effectué | J14: Finalité(s) du traitement effectué
A15: Finalité principale | B15: Compte utilisateur | J15: Finalité principale | K15: Recommander à l'utilisateur des vêtements en fonction de ses préférences
A16: Sous-finalité 1 | B16: Permettre à l'utilisateur de créer un compte | J16: Sous-finalité 1 | K16: Bénéficier de proposition de vêtement par l'algorithme de l'application
A17: Sous-finalité 2 | B17: Permettre à l'utilisateur de se connecter à son compte | J17: Sous-finalité 2 | K17: Bénéficier de préférences personnalisées de contenus, marques ou influenceurs
A18: Sous-finalité 3 | B18: Permet à l'utilisateur de passer une commande | J18: Sous-finalité 3 | K18: Recevoir des recommandations de blogs, conseils, style
A19: Sous-finalité 4 | B19: Permet à l'utilisateur de réaliser une transaction et de recevoir ses articles | J19: Sous-finalité 4 | K19: Améliorer le contenu et l'expérience utilisateur sur l'application
A20: Sous-finalité 5 | B20: Permet à l'utilisateur de gérer ses préférences en matière de données personnelles | J20: Sous-finalité 5
A22: Catégories de données personnelles concernées | B22: Description | E22: Durée de conservation | J22: Catégories de données personnelles concernées | K22: Description | N22: Durée de conservation
A23: État civil, identité, données d'identification, images… | B23: Noms, prénoms, adresses | E23: 5 ans après chaque validation des conditions d'utilisation | J23: État civil, identité, données d'identification, images… | K23: Photos (visage et corps) | N23: 5 ans après chaque validation des conditions d'utilisation
A24: Vie personnelle (habitudes de vie, situation familiale, etc.) | B24: RIB, Numéro de carte bleue | E24: 5 ans après chaque validation des conditions d'utilisation | J24: Vie personnelle (habitudes de vie, situation familiale, etc.) | K24: habitude vestimentaires, mensurations (tour de hanche, tour de bras, tour de poitrine…) | N24: 5 ans après chaque validation des conditions d'utilisation
A25: Informations d'ordre économique et financier (revenus, situation financière, situation fiscale, etc.) | J25: Informations d'ordre économique et financier (revenus, situation financière, situation fiscale, etc.)
A26: Données de connexion (adress IP, logs, etc.) | B26: Adresse IP, navigateur web, appareil (smartphone ou ordinateur) | E26: 5 ans après chaque validation des conditions d'utilisation | J26: Données de connexion (adress IP, logs, etc.) | K26: Adresse IP, navigateur web, appareil (smartphone ou ordinateur) | N26: 5 ans après chaque validation des conditions d'utilisation
A27: Données de localisation (déplacements, données GPS, GSM, etc.) | J27: Données de localisation (déplacements, données GPS, GSM, etc.)
A28: Numéro de Sécurité Sociale (ou NIR) | J28: Numéro de Sécurité Sociale (ou NIR)
A30: Données sensibles | B30: Description | E30: Durée de conservation | J30: Données sensibles | K30: Description | N30: Durée de conservation
A31: Données révélant l'origine raciale ou ethnique | J31: Données révélant l'origine raciale ou ethnique
A32: Données révélant les opinions politiques | J32: Données révélant les opinions politiques
A33: Données révélant les convictions religieuses ou philosophiques | J33: Données révélant les convictions religieuses ou philosophiques
A34: Données révélant l'appartenance syndicale | J34: Données révélant l'appartenance syndicale
A35: Données génétiques | J35: Données génétiques
A36: Données biométriques aux fins d'identifier une personne physique de manière unique | J36: Données biométriques aux fins d'identifier une personne physique de manière unique
A37: Données concernant la santé | J37: Données concernant la santé
A38: Données concernant la vie sexuelle ou l'orientation sexuelle | J38: Données concernant la vie sexuelle ou l'orientation sexuelle
A39: Données relatives à des condamnations pénales ou infractions | J39: Données relatives à des condamnations pénales ou infractions
A41: Catégories de personnes concernées | B41: Description | E41: Précisions | J41: Catégories de personnes concernées | K41: Description | N41: Précisions
A42: Catégorie de personnes 1 | B42: Utilisateurs | E42: Toutes personnes qui ayant accepté les conditions d'utilisations possède un compte utilisateur sur l'application. | J42: Catégorie de personnes 1 | K42: Utilisateurs | N42: Toutes personnes qui ayant accepté les conditions d'utilisations possède un compte utilisateur sur l'application.
A43: Catégorie de personnes 2 | J43: Catégorie de personnes 2
A45: Destinataires | B45: Type de destinataire | E45: Précisions | J45: Destinataires | K45: Type de destinataire | N45: Précisions
A46: Destinataire 1 | B46: Service Data | E46: Pour alimenter les algorithmes de recommandation. | J46: Destinataire 1 | K46: Service Data | N46: Pour alimenter les alogrithme de recommandation.
...

Sheet Analyse Risques
A1: Type de risque | B1: Facteurs de risque | C1: Risque | D1: Conséquences | E1: Impact | F1: Probabilité | G1: Criticité | H1: Actions de prévention | I1: Action de correction
C2: (événement redouté) | D2: (en coût, délai, qualité, satisfaction client) | E2: (0 à3) | F2: (0 à 3) | G2: (impact*prob) | H2: (pour éviter l'événement redouté) | I2: (si événement redouté avéré)
B3: Etant donné que … | C3: Si … | D3: Alors …
A4: Risque technique | B4: les systèmes informatiques sont vulnérables aux failles de sécurité (intrusions, bugs…) | C4: une faille de sécurité est découverte dans l'application | D4: cela pourrait permettre à des pirates informatiques d'accéder aux données des utilisateurs ou de prendre le contrôle de l'application. | E4: 3 | F4: 3 | G4: 9 | H4: - Effectuer des tests de pénétration pour identifier et corriger les failles de sécurité. - Mettre à jour régulièrement les logiciels, frameworks, kernel et les systèmes d'exploitation. - Appliquer le principe du moindre privilège, en donnant aux utilisateurs et aux systèmes uniquement les accès nécessaires. - Mettre en place un plan de réponse aux incidents pour gérer les failles de sécurité. | I4: - Activer immédiatement le plan de réponse aux incidents. - Isoler les systèmes compromis pour limiter la propagation. - Informer les utilisateurs concernés selon les obligations légales. - Corriger la faille de sécurité via un correctif (patch). - Réaliser une analyse post-incident pour éviter la récurrence.
A5: Risque juridique et de conformité | B5: l'application collecte et traite les données personnelles des utilisateurs (photos, noms, adresse…) | C5: ces données ne sont pas sécurisées | D5: il pourrait y avoir des vols, des fraudes, des demandes de rançons. | E5: 3 | F5: 3 | G5: 9 | H5: - Utiliser le chiffrement, le contrôle d'accès et l'anonymisation. - Limiter la collecte et le stockage des données personnelles au strict minimum. - Se conformer aux réglementations applicables en matière de protection des données, telles que le RGPD. | I5: - Notifier la CNIL et les utilisateurs concernés dans les délais réglementaires. - Identifier et corriger la faille ou l'origine de la fuite de données. - Renforcer les mesures de sécurité (chiffrement, accès…). - Réaliser un audit de sécurité et adapter les procédures.
A6: Risque juridique et de conformité | B6: l'application collecte et traite les données personnelles des utilisateurs (photos, noms, adresse…) | C6: nos traitements ne sont pas conforme à la RGPD | D6: nous pourrions être sanctionner par des amandes et poiursuites judiciaires | E6: 3 | F6: 2 | G6: 6 | H6: - Se renseigner sur la RGPD et veiller à être à jour régulièrement. - Mettre en place des mesures de protection des données pour garantir la collecte, le traitement et le stockage des données des utilisateurs conformément à la loi. - Obtenir le consentement des utilisateurs pour la collecte et l'utilisation de leurs données personnelles. - Offrir aux utilisateurs des options pour contrôler et gérer leurs données personnelles. | I6: - Corriger les traitements non conformes (ajout de consentement, suppression des données mal stockées…). - Coopérer avec les autorités de protection des données (ex. CNIL). - Mettre en œuvre immédiatement les mesures correctrices recommandées. - Former les équipes sur la conformité RGPD.
A7: Risque concurrentiel | B7: le marché de l'e-commerce est en pleine effervescence. | C7: si de nouveaux concurrents arrivent sur le marché. | D7: notre part de marché pourrait se réduire. | E7: 2 | F7: 3 | G7: 6 | H7: - Réaliser régulièrement un Benchmark - Adapter notre stratégie | I7: - Réagir rapidement en ajustant l’offre ou les prix. - Lancer une campagne marketing ciblée pour fidéliser les clients existants. - Identifier les leviers de différenciation à mettre en avant. - Réévaluer la stratégie produit ou service.
A8: Risque technique | B8: le developpement de se type d'application est complexe et que c'est notre première application. | C8: nous manquons de ressources (humaines, financières…) | D8: cela pourrait entraîner des retards, des blocages, des dépassements de bugets. | E8: 3 | F8: 3 | G8: 9 | H8: - Faire des points projets réguliers. - Décomposer le projet en tâches plus petites et gérables. - Définir des objectifs SMART avec des jalons et des échéances claires. - Provisionner un bugdet pour imprévus ou retards | I8: - Réévaluer la planification du projet et prioriser les tâches critiques. - Rechercher des financements ou optimiser les ressources disponibles. - Recruter ou faire appel à des prestataires externes. - Revoir les objectifs à court terme pour assurer la livraison minimale viable.
A9: Risque technique | B9: la collaboration et la coordination entre les équipes est primordiale | C9: la coordination et la communication sont défaillantes | D9: cela pourrait entraîner également du retards, des besoins mal compris, du travail en doublons ou du livrable à rattraper. | E9: 3 | F9: 1 | G9: 3 | H9: - Établir des canaux de communication clairs et ouverts entre les membres de l'équipe. - Organiser des réunions régulières pour discuter de l'avancement du projet, des problèmes et des solutions. - Utiliser des outils de gestion de projet pour faciliter la collaboration et le partage de fichiers. | I9: - Mettre en place un plan d’urgence de réorganisation du travail. - Clarifier les rôles et responsabilités immédiatement. - Réaliser un point collectif pour identifier les blocages et remettre tout le monde sur la même longueur d’onde. - Affecter un coordinateur de projet si besoin.
A10: Risque organisationnel | B10: modules de l'application sont imbriqués. | C10: des problèmes de compatibilité ou de communication surviennent. | D10: cela pourrait causer des dysfonctionnement. | E10: 2 | F10: 1 | G10: 2 | H10: - Mettre à jours les langages de programmation, les librairies - réaliser des test régulier, - veiller à la compatibilité entre les technologies | I10: - Identifier les modules problématiques via des tests de diagnostic. - Corriger ou isoler les modules défaillants. - Mettre à jour ou refactoriser les composants incompatibles. - Mettre en place une meilleure documentation d’intégration.
A11: Risque technique | B11: nous dépendons des infrastructures Big Data de fournisseurs tiers | C11: le fournisseurs tiers rencontre des dysfoncionnement | D11: cela pourrait rompre le fonctionnement de l'application. | E11: 3 | F11: 1 | G11: 3 | H11: - Choisir un fournisseur d'API fiable et réputé. - Négocier un contrat de niveau de service (SLA) avec le fournisseur pour garantir la disponibilité et les performances de l'API. - Utiliser des back-ups (instantanée) - Avoir un contrat avec un autre fournisseurs big data pour répartir le risque | I11: - Basculer sur la solution de secours ou le fournisseur alternatif prévu. - Contacter immédiatement le fournisseur pour connaître les délais de résolution. - Informer les utilisateurs des impacts possibles. - Évaluer la pertinence du fournisseur pour de futurs projets.
A12: Risque technique | B12: notre application utilise une quantité massive de données | C12: nous sous estimons le volume de données à traiter. | D12: cela pourrait entraîner des ralentissements dans l'application et détèriorer l'expérience utilisateur | E12: 2 | F12: 1 | G12: 2 | H12: - Choisir une infrastucture performante et scalable. -Optimiser les requêtes API pour réduire la charge du serveur. -Mettre en place des mécanismes de mise en cache pour les données fréquemment consultées. | I12: - Augmenter les capacités de l’infrastructure (scalabilité verticale ou horizontale). - Optimiser les requêtes et les bases de données. - Mettre en place une architecture de traitement distribuée si nécessaire (ex: Spark). - Prioriser les fonctionnalités critiques pour garantir la performance minimale.
B14: occurrence | C14: Criticité moyenne
A15: Risque technique | B15: =COUNTIF(A4:A12,"Risque technique") -> 5 | C15: =AVERAGE(G12,G11,G9,G8,G4) -> 5.2
A16: Risque juridique et de conformité | B16: =COUNTIF(A4:A12,"Risque juridique et de conformité") -> 2 | C16: =AVERAGE(G5,G6) -> 7.5
A17: Risque concurrentiel | B17: =COUNTIF(A4:A12,"Risque concurrentiel") -> 1 | C17: =G10 -> 2
A18: Risque organisationnel | B18: =COUNTIF(A4:A12,"Risque organisationnel") -> 1 | C18: =G10 -> 2
